#VRML_SIM R2019a utf8
WorldInfo {
}
Viewpoint {
  orientation 0.03026389201193155 -0.9974311544872596 -0.06492448612428434 4.012013337462635
  position 0.30592981412456444 0.16928282070391137 -0.34781147748364366
}
TexturedBackground {
}
TexturedBackgroundLight {
}
Floor {
}
Robot {
  translation 0 0.035 0
  children [
    DEF ROBOT_BODY Shape {
      appearance PBRAppearance {
        baseColor 0.45098039215686275 0.8235294117647058 0.08627450980392157
      }
      geometry DEF G_BODY Box {
        size 0.25 0.07 0.1
      }
    }
    DEF WHEEL_1_JOINT HingeJoint {
      jointParameters HingeJointParameters {
        axis 0 0 1
        anchor -0.05 0 0.06
      }
      device [
        RotationalMotor {
          name "motor_right"
        }
      ]
      endPoint DEF WHEEL1 Solid {
        translation -0.05 0 0.06
        rotation 1 0 0 1.5707996938995745
        children [
          Shape {
            appearance DEF A_WHEEL1 PBRAppearance {
              baseColor 0 0 0
              roughness 1
              metalness 0
            }
            geometry DEF G_WHEEL Cylinder {
              height 0.02
              radius 0.075
            }
          }
          HingeJoint {
            endPoint DEF WHEEL2 Solid {
              translation 0 -0.12 0
              children [
                Shape {
                  appearance USE A_WHEEL1
                  geometry USE G_WHEEL
                }
              ]
            }
          }
        ]
        boundingObject USE G_WHEEL
        physics Physics {
        }
      }
    }
  ]
  boundingObject USE G_BODY
  physics Physics {
  }
  controller "Robot1"
}
