#VRML_SIM R2019a utf8
WorldInfo {
}
Viewpoint {
  orientation 0.9146827397731343 0.3935292723436479 0.09214226701026904 5.781981545982214
  position -0.0858349983643738 0.287339988063618 0.5375676439960233
}
TexturedBackground {
}
TexturedBackgroundLight {
}
Floor {
}
Robot {
  translation 0 0.035 0
  children [
    DEF ROBOT_BODY Shape {
      appearance PBRAppearance {
        baseColor 0.45098039215686275 0.8235294117647058 0.08627450980392157
      }
      geometry DEF G_BODY Box {
        size 0.25 0.07 0.1
      }
    }
    DEF WHEEL_1_JOINT HingeJoint {
      jointParameters HingeJointParameters {
        axis 0 0 1
        anchor -0.05 0 0.06
      }
      endPoint DEF WHEEL1 Solid {
        translation -0.05 0 0.06
        rotation 1 0 0 1.5707996938995745
        children [
          Shape {
            appearance PBRAppearance {
              baseColor 0 0 0
              roughness 1
              metalness 0
            }
            geometry DEF G_WHEEL Cylinder {
              height 0.02
              radius 0.075
            }
          }
        ]
        boundingObject USE G_WHEEL
        physics Physics {
        }
      }
    }
  ]
  boundingObject USE G_BODY
  physics Physics {
  }
}
