#VRML_SIM R2019a utf8
WorldInfo {
}
Viewpoint {
  orientation 0.3690450045046609 0.9289933221738174 0.0278781636161494 6.120911750124002
  position -0.10924890392977132 0.08271551279012865 0.56697522540484
}
TexturedBackground {
}
TexturedBackgroundLight {
}
Floor {
}
Robot {
  children [
    Solid {
      translation 0 0.035 0
      rotation -0.8749826679791802 0.3253476248823975 -0.358544632813571 4.4620774168869164e-05
      children [
        Shape {
          appearance PBRAppearance {
            baseColor 0.5411764705882353 0.8862745098039215 0.20392156862745098
          }
          geometry Box {
            size 0.25 0.07 0.1
          }
        }
        HingeJoint {
          jointParameters HingeJointParameters {
            position -0.01311769559151029
            axis 0 0 1
            anchor -0.051 0 0
          }
          device [
            RotationalMotor {
              name "motor"
            }
          ]
          endPoint Solid {
            translation -0.05010438782248953 -0.0006689832890170672 0.059999979529963485
            rotation 0.3730684285790452 -0.6560651602284066 -0.6560475997456565 2.427400622348508
            children [
              Shape {
                appearance DEF A_CYL1 PBRAppearance {
                  baseColor 0.12549019607843137 0.2901960784313726 0.5294117647058824
                }
                geometry Cylinder {
                  height 0.02
                  radius 0.075
                }
              }
            ]
            boundingObject Cylinder {
              height 0.02
              radius 0.075
            }
            physics Physics {
            }
          }
        }
      ]
      boundingObject Box {
        size 0.25 0.07 0.1
      }
      physics Physics {
      }
    }
  ]
  controller "Robot1"
}
