#VRML_SIM R2019a utf8
WorldInfo {
}
Viewpoint {
  orientation 0.984903924848212 -0.1714828925572677 -0.02361940682531684 6.005292813187068
  position 0.06360540724491563 0.33816775237698216 0.5368947511582588
}
TexturedBackground {
}
TexturedBackgroundLight {
}
Floor {
}
Robot {
  translation 0 0.1 0
  rotation 1 0 0 0
  children [
    DEF GR_BODY Group {
      children [
        DEF ROBOT_BODY Shape {
          appearance PBRAppearance {
            baseColor 0.45098039215686275 0.8235294117647058 0.08627450980392157
          }
          geometry DEF G_BODY Box {
            size 0.25 0.07 0.1
          }
        }
        Transform {
          translation 0.11 -0.05 0
          children [
            Shape {
              appearance PBRAppearance {
                baseColor 0.9333333333333333 0.9333333333333333 0.9254901960784314
                roughness 1
                metalness 0
              }
              geometry Sphere {
                radius 0.015
              }
            }
          ]
        }
      ]
    }
    DEF ROBOT_BODY Shape {
      appearance PBRAppearance {
        baseColor 0.45098039215686275 0.8235294117647058 0.08627450980392157
      }
      geometry DEF G_BODY Box {
        size 0.25 0.07 0.1
      }
    }
    DEF WHEEL_1_JOINT HingeJoint {
      jointParameters HingeJointParameters {
        axis 0 0 1
        anchor -0.05 0 0.06
      }
      device [
        PositionSensor {
          name "encoder1"
        }
        RotationalMotor {
          name "motor_right"
        }
      ]
      endPoint DEF WHEEL1 Solid {
        translation -0.05 0 0.06
        rotation 1 0 0 1.5707996938995745
        children [
          Shape {
            appearance DEF A_WHEEL1 PBRAppearance {
              baseColor 0 0 0
              roughness 1
              metalness 0
            }
            geometry DEF G_WHEEL Cylinder {
              height 0.02
              radius 0.075
            }
          }
        ]
        boundingObject USE G_WHEEL
        physics Physics {
        }
      }
    }
    DEF WHEEL_2 HingeJoint {
      jointParameters HingeJointParameters {
        axis 0 0 1
        anchor -0.05 0 -0.06
      }
      device [
        RotationalMotor {
          name "motor_left"
        }
      ]
      endPoint Solid {
        translation -0.05 0 -0.06
        rotation -1 0 0 1.5708003061004252
        children [
          Shape {
            appearance USE A_WHEEL1
            geometry USE G_WHEEL
          }
        ]
        name "solid(1)"
        boundingObject USE G_WHEEL
        physics Physics {
        }
      }
    }
    DistanceSensor {
      translation 0.125 0 0
      children [
        Shape {
          appearance PBRAppearance {
            baseColor 0.9882352941176471 0.9137254901960784 0.30980392156862746
          }
          geometry Box {
            size 0.02 0.01 0.01
          }
        }
      ]
      name "distance_sensor"
      lookupTable [
        0 0 0
        0.02 0 0
        11 1023 0
      ]
      resolution 1
    }
  ]
  boundingObject USE GR_BODY
  physics Physics {
  }
  controller "Robot1"
}
Solid {
  translation 0.5600000000000003 0.05 0
  children [
    Shape {
      appearance PBRAppearance {
        baseColor 0.4470588235294118 0.6235294117647059 0.8117647058823529
      }
      geometry DEF G_OBSTACLE Box {
        size 0.1 0.1 0.1
      }
    }
  ]
  boundingObject USE G_OBSTACLE
}
